Workbook

Sheet Absensi Bulanan
A2: REKAPITULASI & FORM ABSENSI KARYAWAN
B4: Tahun | C4: 2026 | D4: Periode: | E4: =TEXT(DATE(C4, VLOOKUP(C5, Pengaturan!A2:B13, 2, FALSE), 1), "MMMM YYYY") -> August 2026 | H4: Petunjuk Kode: | I4: H | J4: Hadir | K4: S | L4: Sakit | M4: I | N4: Izin | O4: A | P4: Alfa | Q4: C | R4: Cuti | S4: OFF | T4: Libur
B5: Bulan | C5: Agustus
B6: Filter Status: | C6: Tampilkan Semua
A7: No | B7: NOKA / NIK | C7: Nama Karyawan | D7: Posisi | E7: ="REKAPITULASI & FORM ABSENSI KARYAWAN BULAN " & UPPER($C$5) & " " & $C$4 -> REKAPITULASI & FORM ABSENSI KARYAWAN BULAN AGUSTUS 2026 | AJ7: H | AK7: S | AL7: I | AM7: A | AN7: C | AO7: % Hadir
E8: =IF(1<=DAY(EOMONTH(DATE($C$4,VLOOKUP($C$5,Pengaturan!$A$2:$B$13,2,FALSE),1),0)),1,"") -> 1 | F8: =IF(2<=DAY(EOMONTH(DATE($C$4,VLOOKUP($C$5,Pengaturan!$A$2:$B$13,2,FALSE),1),0)),2,"") -> 2 | G8: =IF(3<=DAY(EOMONTH(DATE($C$4,VLOOKUP($C$5,Pengaturan!$A$2:$B$13,2,FALSE),1),0)),3,"") -> 3 | H8: =IF(4<=DAY(EOMONTH(DATE($C$4,VLOOKUP($C$5,Pengaturan!$A$2:$B$13,2,FALSE),1),0)),4,"") -> 4 | I8: =IF(5<=DAY(EOMONTH(DATE($C$4,VLOOKUP($C$5,Pengaturan!$A$2:$B$13,2,FALSE),1),0)),5,"") -> 5 | J8: =IF(6<=DAY(EOMONTH(DATE($C$4,VLOOKUP($C$5,Pengaturan!$A$2:$B$13,2,FALSE),1),0)),6,"") -> 6 | K8: =IF(7<=DAY(EOMONTH(DATE($C$4,VLOOKUP($C$5,Pengaturan!$A$2:$B$13,2,FALSE),1),0)),7,"") -> 7 | L8: =IF(8<=DAY(EOMONTH(DATE($C$4,VLOOKUP($C$5,Pengaturan!$A$2:$B$13,2,FALSE),1),0)),8,"") -> 8 | M8: =IF(9<=DAY(EOMONTH(DATE($C$4,VLOOKUP($C$5,Pengaturan!$A$2:$B$13,2,FALSE),1),0)),9,"") -> 9 | N8: =IF(10<=DAY(EOMONTH(DATE($C$4,VLOOKUP($C$5,Pengaturan!$A$2:$B$13,2,FALSE),1),0)),10,"") -> 10 | O8: =IF(11<=DAY(EOMONTH(DATE($C$4,VLOOKUP($C$5,Pengaturan!$A$2:$B$13,2,FALSE),1),0)),11,"") -> 11 | P8: =IF(12<=DAY(EOMONTH(DATE($C$4,VLOOKUP($C$5,Pengaturan!$A$2:$B$13,2,FALSE),1),0)),12,"") -> 12 | Q8: =IF(13<=DAY(EOMONTH(DATE($C$4,VLOOKUP($C$5,Pengaturan!$A$2:$B$13,2,FALSE),1),0)),13,"") -> 13 | R8: =IF(14<=DAY(EOMONTH(DATE($C$4,VLOOKUP($C$5,Pengaturan!$A$2:$B$13,2,FALSE),1),0)),14,"") -> 14 | S8: =IF(15<=DAY(EOMONTH(DATE($C$4,VLOOKUP($C$5,Pengaturan!$A$2:$B$13,2,FALSE),1),0)),15,"") -> 15 | T8: =IF(16<=DAY(EOMONTH(DATE($C$4,VLOOKUP($C$5,Pengaturan!$A$2:$B$13,2,FALSE),1),0)),16,"") -> 16 | U8: =IF(17<=DAY(EOMONTH(DATE($C$4,VLOOKUP($C$5,Pengaturan!$A$2:$B$13,2,FALSE),1),0)),17,"") -> 17 | V8: =IF(18<=DAY(EOMONTH(DATE($C$4,VLOOKUP($C$5,Pengaturan!$A$2:$B$13,2,FALSE),1),0)),18,"") -> 18 | W8: =IF(19<=DAY(EOMONTH(DATE($C$4,VLOOKUP($C$5,Pengaturan!$A$2:$B$13,2,FALSE),1),0)),19,"") -> 19 | X8: =IF(20<=DAY(EOMONTH(DATE($C$4,VLOOKUP($C$5,Pengaturan!$A$2:$B$13,2,FALSE),1),0)),20,"") -> 20 | Y8: =IF(21<=DAY(EOMONTH(DATE($C$4,VLOOKUP($C$5,Pengaturan!$A$2:$B$13,2,FALSE),1),0)),21,"") -> 21 | Z8: =IF(22<=DAY(EOMONTH(DATE($C$4,VLOOKUP($C$5,Pengaturan!$A$2:$B$13,2,FALSE),1),0)),22,"") -> 22 | AA8: =IF(23<=DAY(EOMONTH(DATE($C$4,VLOOKUP($C$5,Pengaturan!$A$2:$B$13,2,FALSE),1),0)),23,"") -> 23 | AB8: =IF(24<=DAY(EOMONTH(DATE($C$4,VLOOKUP($C$5,Pengaturan!$A$2:$B$13,2,FALSE),1),0)),24,"") -> 24 | AC8: =IF(25<=DAY(EOMONTH(DATE($C$4,VLOOKUP($C$5,Pengaturan!$A$2:$B$13,2,FALSE),1),0)),25,"") -> 25 | AD8: =IF(26<=DAY(EOMONTH(DATE($C$4,VLOOKUP($C$5,Pengaturan!$A$2:$B$13,2,FALSE),1),0)),26,"") -> 26 | AE8: =IF(27<=DAY(EOMONTH(DATE($C$4,VLOOKUP($C$5,Pengaturan!$A$2:$B$13,2,FALSE),1),0)),27,"") -> 27 | AF8: =IF(28<=DAY(EOMONTH(DATE($C$4,VLOOKUP($C$5,Pengaturan!$A$2:$B$13,2,FALSE),1),0)),28,"") -> 28 | AG8: =IF(29<=DAY(EOMONTH(DATE($C$4,VLOOKUP($C$5,Pengaturan!$A$2:$B$13,2,FALSE),1),0)),29,"") -> 29 | AH8: =IF(30<=DAY(EOMONTH(DATE($C$4,VLOOKUP($C$5,Pengaturan!$A$2:$B$13,2,FALSE),1),0)),30,"") -> 30 | AI8: =IF(31<=DAY(EOMONTH(DATE($C$4,VLOOKUP($C$5,Pengaturan!$A$2:$B$13,2,FALSE),1),0)),31,"") -> 31
A9: =IF('Data Karyawan'!A4<>"", 'Data Karyawan'!A4, "") -> 1 | B9: =IF('Data Karyawan'!B4<>"", 'Data Karyawan'!B4, "") -> 80094 | C9: =IF('Data Karyawan'!C4<>"", 'Data Karyawan'!C4, "") -> Siti Zulfatul | D9: =IF('Data Karyawan'!D4<>"", 'Data Karyawan'!D4, "") -> A1 | AJ9: =IF($C9="","",COUNTIF(E9:AI9, "H")) -> 0 | AK9: =IF($C9="","",COUNTIF(E9:AI9, "S")) -> 0 | AL9: =IF($C9="","",COUNTIF(E9:AI9, "I")) -> 0 | AM9: =IF($C9="","",COUNTIF(E9:AI9, "A")) -> 0 | AN9: =IF($C9="","",COUNTIF(E9:AI9, "C")) -> 0 | AO9: =IF(OR($B9="",(AJ9+AK9+AL9+AM9)=0),0,AJ9/(AJ9+AK9+AL9+AM9)) -> 0
A10: =IF('Data Karyawan'!A5<>"", 'Data Karyawan'!A5, "") -> 2 | B10: =IF('Data Karyawan'!B5<>"", 'Data Karyawan'!B5, "") -> 80095 | C10: =IF('Data Karyawan'!C5<>"", 'Data Karyawan'!C5, "") -> Eko Riski W | D10: =IF('Data Karyawan'!D5<>"", 'Data Karyawan'!D5, "") -> A1 | AJ10: =IF($C10="","",COUNTIF(E10:AI10, "H")) -> 0 | AK10: =IF($C10="","",COUNTIF(E10:AI10, "S")) -> 0 | AL10: =IF($C10="","",COUNTIF(E10:AI10, "I")) -> 0 | AM10: =IF($C10="","",COUNTIF(E10:AI10, "A")) -> 0 | AN10: =IF($C10="","",COUNTIF(E10:AI10, "C")) -> 0 | AO10: =IF(OR($B10="",(AJ10+AK10+AL10+AM10)=0),0,AJ10/(AJ10+AK10+AL10+AM10)) -> 0
A11: =IF('Data Karyawan'!A6<>"", 'Data Karyawan'!A6, "") -> 3 | B11: =IF('Data Karyawan'!B6<>"", 'Data Karyawan'!B6, "") -> 80097 | C11: =IF('Data Karyawan'!C6<>"", 'Data Karyawan'!C6, "") -> Wiyan Asri | D11: =IF('Data Karyawan'!D6<>"", 'Data Karyawan'!D6, "") -> A1 | AJ11: =IF($C11="","",COUNTIF(E11:AI11, "H")) -> 0 | AK11: =IF($C11="","",COUNTIF(E11:AI11, "S")) -> 0 | AL11: =IF($C11="","",COUNTIF(E11:AI11, "I")) -> 0 | AM11: =IF($C11="","",COUNTIF(E11:AI11, "A")) -> 0 | AN11: =IF($C11="","",COUNTIF(E11:AI11, "C")) -> 0 | AO11: =IF(OR($B11="",(AJ11+AK11+AL11+AM11)=0),0,AJ11/(AJ11+AK11+AL11+AM11)) -> 0
A12: =IF('Data Karyawan'!A7<>"", 'Data Karyawan'!A7, "") -> 4 | B12: =IF('Data Karyawan'!B7<>"", 'Data Karyawan'!B7, "") -> 80098 | C12: =IF('Data Karyawan'!C7<>"", 'Data Karyawan'!C7, "") -> Siti Rohmawati | D12: =IF('Data Karyawan'!D7<>"", 'Data Karyawan'!D7, "") -> A1 | AJ12: =IF($C12="","",COUNTIF(E12:AI12, "H")) -> 0 | AK12: =IF($C12="","",COUNTIF(E12:AI12, "S")) -> 0 | AL12: =IF($C12="","",COUNTIF(E12:AI12, "I")) -> 0 | AM12: =IF($C12="","",COUNTIF(E12:AI12, "A")) -> 0 | AN12: =IF($C12="","",COUNTIF(E12:AI12, "C")) -> 0 | AO12: =IF(OR($B12="",(AJ12+AK12+AL12+AM12)=0),0,AJ12/(AJ12+AK12+AL12+AM12)) -> 0
A13: =IF('Data Karyawan'!A8<>"", 'Data Karyawan'!A8, "") -> 5 | B13: =IF('Data Karyawan'!B8<>"", 'Data Karyawan'!B8, "") -> 80099 | C13: =IF('Data Karyawan'!C8<>"", 'Data Karyawan'!C8, "") -> Syaifira Ila | D13: =IF('Data Karyawan'!D8<>"", 'Data Karyawan'!D8, "") -> A1 | AJ13: =IF($C13="","",COUNTIF(E13:AI13, "H")) -> 0 | AK13: =IF($C13="","",COUNTIF(E13:AI13, "S")) -> 0 | AL13: =IF($C13="","",COUNTIF(E13:AI13, "I")) -> 0 | AM13: =IF($C13="","",COUNTIF(E13:AI13, "A")) -> 0 | AN13: =IF($C13="","",COUNTIF(E13:AI13, "C")) -> 0 | AO13: =IF(OR($B13="",(AJ13+AK13+AL13+AM13)=0),0,AJ13/(AJ13+AK13+AL13+AM13)) -> 0
A14: =IF('Data Karyawan'!A9<>"", 'Data Karyawan'!A9, "") -> 6 | B14: =IF('Data Karyawan'!B9<>"", 'Data Karyawan'!B9, "") -> 80100 | C14: =IF('Data Karyawan'!C9<>"", 'Data Karyawan'!C9, "") -> Hidayatus Sholikhah | D14: =IF('Data Karyawan'!D9<>"", 'Data Karyawan'!D9, "") -> A1 | AJ14: =IF($C14="","",COUNTIF(E14:AI14, "H")) -> 0 | AK14: =IF($C14="","",COUNTIF(E14:AI14, "S")) -> 0 | AL14: =IF($C14="","",COUNTIF(E14:AI14, "I")) -> 0 | AM14: =IF($C14="","",COUNTIF(E14:AI14, "A")) -> 0 | AN14: =IF($C14="","",COUNTIF(E14:AI14, "C")) -> 0 | AO14: =IF(OR($B14="",(AJ14+AK14+AL14+AM14)=0),0,AJ14/(AJ14+AK14+AL14+AM14)) -> 0
A15: =IF('Data Karyawan'!A10<>"", 'Data Karyawan'!A10, "") -> 7 | B15: =IF('Data Karyawan'!B10<>"", 'Data Karyawan'!B10, "") -> 80101 | C15: =IF('Data Karyawan'!C10<>"", 'Data Karyawan'!C10, "") -> Erika Nur Manda | D15: =IF('Data Karyawan'!D10<>"", 'Data Karyawan'!D10, "") -> A1 | AJ15: =IF($C15="","",COUNTIF(E15:AI15, "H")) -> 0 | AK15: =IF($C15="","",COUNTIF(E15:AI15, "S")) -> 0 | AL15: =IF($C15="","",COUNTIF(E15:AI15, "I")) -> 0 | AM15: =IF($C15="","",COUNTIF(E15:AI15, "A")) -> 0 | AN15: =IF($C15="","",COUNTIF(E15:AI15, "C")) -> 0 | AO15: =IF(OR($B15="",(AJ15+AK15+AL15+AM15)=0),0,AJ15/(AJ15+AK15+AL15+AM15)) -> 0
A16: =IF('Data Karyawan'!A11<>"", 'Data Karyawan'!A11, "") -> 8 | B16: =IF('Data Karyawan'!B11<>"", 'Data Karyawan'!B11, "") -> 80102 | C16: =IF('Data Karyawan'!C11<>"", 'Data Karyawan'!C11, "") -> M. Alfarizd | D16: =IF('Data Karyawan'!D11<>"", 'Data Karyawan'!D11, "") -> A1 | AJ16: =IF($C16="","",COUNTIF(E16:AI16, "H")) -> 0 | AK16: =IF($C16="","",COUNTIF(E16:AI16, "S")) -> 0 | AL16: =IF($C16="","",COUNTIF(E16:AI16, "I")) -> 0 | AM16: =IF($C16="","",COUNTIF(E16:AI16, "A")) -> 0 | AN16: =IF($C16="","",COUNTIF(E16:AI16, "C")) -> 0 | AO16: =IF(OR($B16="",(AJ16+AK16+AL16+AM16)=0),0,AJ16/(AJ16+AK16+AL16+AM16)) -> 0
A17: =IF('Data Karyawan'!A12<>"", 'Data Karyawan'!A12, "") -> 9 | B17: =IF('Data Karyawan'!B12<>"", 'Data Karyawan'!B12, "") -> 80103 | C17: =IF('Data Karyawan'!C12<>"", 'Data Karyawan'!C12, "") -> Nazar Putra A. | D17: =IF('Data Karyawan'!D12<>"", 'Data Karyawan'!D12, "") -> A1 | AJ17: =IF($C17="","",COUNTIF(E17:AI17, "H")) -> 0 | AK17: =IF($C17="","",COUNTIF(E17:AI17, "S")) -> 0 | AL17: =IF($C17="","",COUNTIF(E17:AI17, "I")) -> 0 | AM17: =IF($C17="","",COUNTIF(E17:AI17, "A")) -> 0 | AN17: =IF($C17="","",COUNTIF(E17:AI17, "C")) -> 0 | AO17: =IF(OR($B17="",(AJ17+AK17+AL17+AM17)=0),0,AJ17/(AJ17+AK17+AL17+AM17)) -> 0
A18: =IF('Data Karyawan'!A13<>"", 'Data Karyawan'!A13, "") -> 10 | B18: =IF('Data Karyawan'!B13<>"", 'Data Karyawan'!B13, "") -> 80104 | C18: =IF('Data Karyawan'!C13<>"", 'Data Karyawan'!C13, "") -> Dewi Masfufah | D18: =IF('Data Karyawan'!D13<>"", 'Data Karyawan'!D13, "") -> A1 | AJ18: =IF($C18="","",COUNTIF(E18:AI18, "H")) -> 0 | AK18: =IF($C18="","",COUNTIF(E18:AI18, "S")) -> 0 | AL18: =IF($C18="","",COUNTIF(E18:AI18, "I")) -> 0 | AM18: =IF($C18="","",COUNTIF(E18:AI18, "A")) -> 0 | AN18: =IF($C18="","",COUNTIF(E18:AI18, "C")) -> 0 | AO18: =IF(OR($B18="",(AJ18+AK18+AL18+AM18)=0),0,AJ18/(AJ18+AK18+AL18+AM18)) -> 0
A19: =IF('Data Karyawan'!A14<>"", 'Data Karyawan'!A14, "") -> 11 | B19: =IF('Data Karyawan'!B14<>"", 'Data Karyawan'!B14, "") -> 80105 | C19: =IF('Data Karyawan'!C14<>"", 'Data Karyawan'!C14, "") -> Erika Cahya | D19: =IF('Data Karyawan'!D14<>"", 'Data Karyawan'!D14, "") -> A1 | AJ19: =IF($C19="","",COUNTIF(E19:AI19, "H")) -> 0 | AK19: =IF($C19="","",COUNTIF(E19:AI19, "S")) -> 0 | AL19: =IF($C19="","",COUNTIF(E19:AI19, "I")) -> 0 | AM19: =IF($C19="","",COUNTIF(E19:AI19, "A")) -> 0 | AN19: =IF($C19="","",COUNTIF(E19:AI19, "C")) -> 0 | AO19: =IF(OR($B19="",(AJ19+AK19+AL19+AM19)=0),0,AJ19/(AJ19+AK19+AL19+AM19)) -> 0
A20: =IF('Data Karyawan'!A15<>"", 'Data Karyawan'!A15, "") -> 12 | B20: =IF('Data Karyawan'!B15<>"", 'Data Karyawan'!B15, "") -> 80106 | C20: =IF('Data Karyawan'!C15<>"", 'Data Karyawan'!C15, "") -> Heri Setyawan | D20: =IF('Data Karyawan'!D15<>"", 'Data Karyawan'!D15, "") -> A1 | AJ20: =IF($C20="","",COUNTIF(E20:AI20, "H")) -> 0 | AK20: =IF($C20="","",COUNTIF(E20:AI20, "S")) -> 0 | AL20: =IF($C20="","",COUNTIF(E20:AI20, "I")) -> 0 | AM20: =IF($C20="","",COUNTIF(E20:AI20, "A")) -> 0 | AN20: =IF($C20="","",COUNTIF(E20:AI20, "C")) -> 0 | AO20: =IF(OR($B20="",(AJ20+AK20+AL20+AM20)=0),0,AJ20/(AJ20+AK20+AL20+AM20)) -> 0
... A300: =IF('Data Karyawan'!A295<>"", 'Data Karyawan'!A295, "") | B300: =IF('Data Karyawan'!B295<>"", 'Data Karyawan'!B295, "") | C300: =IF('Data Karyawan'!C295<>"", 'Data Karyawan'!C295, "") | D300: =IF('Data Karyawan'!D295<>"", 'Data Karyawan'!D295, "") | AJ300: =IF($C300="","",COUNTIF(E300:AI300, "H")) | AK300: =IF($C300="","",COUNTIF(E300:AI300, "S")) | AL300: =IF($C300="","",COUNTIF(E300:AI300, "I")) | AM300: =IF($C300="","",COUNTIF(E300:AI300, "A")) | AN300: =IF($C300="","",COUNTIF(E300:AI300, "C")) | AO300: =IF(OR($B300="",(AJ300+AK300+AL300+AM300)=0),0,AJ300/(AJ300+AK300+AL300+AM300)) -> #VALUE!
A301: TOTAL KESELURUHAN | E301: =COUNTIF(E9:E300,"H") -> 0 | F301: =COUNTIF(F9:F300,"H") -> 0 | G301: =COUNTIF(G9:G300,"H") -> 0 | H301: =COUNTIF(H9:H300,"H") -> 0 | I301: =COUNTIF(I9:I300,"H") -> 0 | J301: =COUNTIF(J9:J300,"H") -> 0 | K301: =COUNTIF(K9:K300,"H") -> 0 | L301: =COUNTIF(L9:L300,"H") -> 0 | ... AI301: =COUNTIF(AI9:AI300,"H") -> 0 | AJ301: =SUM(AJ9:AJ300) -> 0 | AK301: =SUM(AK9:AK300) -> 0 | AL301: =SUM(AL9:AL300) -> 0 | AM301: =SUM(AM9:AM300) -> 0 | AN301: =SUM(AN9:AN300) -> 0 | AO301: =IFERROR(AVERAGEIF(AO9:AO300,">0"), 0) -> 0

Sheet Data Karyawan
A1: MASTER DATA KARYAWAN
A3: No | B3: NOKA / NIK | C3: Nama Lengkap | D3: Divisi / Departemen | E3: Jabatan | F3: Status Kepegawaian
A4: 1 | B4: 80094 | C4: Siti Zulfatul | D4: A1 | E4: KARYAWAN | F4: AKTIF
A5: 2 | B5: 80095 | C5: Eko Riski W | D5: A1 | E5: KARYAWAN | F5: AKTIF
A6: 3 | B6: 80097 | C6: Wiyan Asri | D6: A1 | E6: KARYAWAN | F6: AKTIF
A7: 4 | B7: 80098 | C7: Siti Rohmawati | D7: A1 | E7: KARYAWAN | F7: AKTIF
A8: 5 | B8: 80099 | C8: Syaifira Ila | D8: A1 | E8: KARYAWAN | F8: AKTIF
A9: 6 | B9: 80100 | C9: Hidayatus Sholikhah | D9: A1 | E9: KARYAWAN | F9: AKTIF
A10: 7 | B10: 80101 | C10: Erika Nur Manda | D10: A1 | E10: KARYAWAN | F10: AKTIF
A11: 8 | B11: 80102 | C11: M. Alfarizd | D11: A1 | E11: KARYAWAN | F11: AKTIF
A12: 9 | B12: 80103 | C12: Nazar Putra A. | D12: A1 | E12: KARYAWAN | F12: AKTIF
A13: 10 | B13: 80104 | C13: Dewi Masfufah | D13: A1 | E13: KARYAWAN | F13: AKTIF
A14: 11 | B14: 80105 | C14: Erika Cahya | D14: A1 | E14: KARYAWAN | F14: AKTIF
A15: 12 | B15: 80106 | C15: Heri Setyawan | D15: A1 | E15: KARYAWAN | F15: AKTIF
... A78: 75 | B78: 80219 | C78: Dinda Khoirunnisak | D78: A1 | E78: KARYAWAN | F78: AKTIF
A79: 76 | C79: Nafiela Rizky R | D79: A1 | E79: KARYAWAN | F79: AKTIF
A80: 77 | B80: 80220 | C80: Cinta Murni Hidayati | D80: A1 | E80: KARYAWAN | F80: AKTIF
A81: 78 | C81: Sheyra Kurnia F | D81: A1 | E81: KARYAWAN | F81: AKTIF
A82: 79 | B82: 80221 | C82: Iva Nur Faidah | D82: A1 | E82: KARYAWAN | F82: AKTIF
A83: 80 | B83: 80222 | C83: Dela Oktavia Rahma | D83: A1 | E83: KARYAWAN | F83: AKTIF
A84: 81 | B84: 80223 | C84: Elsa Esiana P | D84: A1 | E84: KARYAWAN | F84: AKTIF
A85: 82 | B85: 80224 | C85: Pitanti Wahyu | D85: A1 | E85: KARYAWAN | F85: AKTIF
A86: 83 | B86: 80225 | C86: Rochma Ayu Lestari | D86: A1 | E86: KARYAWAN | F86: AKTIF
A87: 84 | B87: 80226 | C87: Febriana Nova C | D87: A1 | E87: KARYAWAN | F87: AKTIF
A88: 85 | B88: 80227 | C88: Silvia Widyanti | D88: A1 | E88: KARYAWAN | F88: AKTIF
A89: 86 | C89: Titik Susanti | D89: A1 | E89: KARYAWAN | F89: AKTIF
A90: 87 | B90: 80228 | C90: Desi Lestari | D90: A1 | E90: KARYAWAN | F90: AKTIF
A91: 88 | C91: Ika Sriwahyuni | D91: A1 | E91: KARYAWAN | F91: AKTIF
A92: 89 | B92: 80241 | C92: Citra Alamanda | D92: A1 | E92: KARYAWAN | F92: AKTIF
A93: 90 | C93: Usfatun Uffanisa | D93: A1 | E93: KARYAWAN | F93: AKTIF
A94: 91 | C94: Nova Riskia Indriani | D94: A1 | E94: KARYAWAN | F94: AKTIF
A95: 92 | C95: Siti Hanifah | D95: A1 | E95: KARYAWAN | F95: AKTIF
A96: 93 | C96: Desi Arum Sari | D96: A1 | E96: KARYAWAN | F96: AKTIF
A97: 94 | C97: Zuke Liana | D97: A1 | E97: KARYAWAN | F97: AKTIF
A98: 95 | B98: 80264 | C98: Putri Anggraini | D98: A1 | E98: KARYAWAN | F98: AKTIF
A99: 96 | B99: 80266 | C99: Siti Zumaroh | D99: A1 | E99: KARYAWAN | F99: AKTIF
A100: 97 | B100: 80265 | C100: Adinda Nurul Izzati | D100: A1 | E100: KARYAWAN | F100: AKTIF
A101: 98 | B101: 80267 | C101: Denisyah Exsanti Anggraini | D101: A1 | E101: KARYAWAN | F101: AKTIF
A102: 99 | C102: Yuana Prisma Dina | D102: A1 | E102: KARYAWAN | F102: AKTIF
A103: 100 | C103: Alycia Salsabila A | D103: A1 | E103: KARYAWAN | F103: AKTIF
...

Sheet Pengaturan
A1: DAFTAR BULAN | B1: NOMOR BULAN | D1: DAFTAR TAHUN | F1: KODE STATUS | G1: KETERANGAN | I1: TANGGAL LIBUR NASIONAL | J1: KETERANGAN LIBUR | L1: STATUS KEPEGAWAIAN | N1: FILTER TAMPILAN ABSENSI
A2: Januari | B2: 1 | D2: 2024 | F2: H | G2: Hadir | I2: =DATE(2026,1,1) -> 46023 | J2: Tahun Baru Masehi | L2: AKTIF | N2: Tampilkan Semua
A3: Februari | B3: 2 | D3: 2025 | F3: S | G3: Sakit | I3: =DATE(2026,1,16) -> 46038 | J3: Isra Mi'raj Nabi Muhammad SAW | L3: OUT | N3: Hanya Karyawan Aktif (Sembunyikan OUT)
A4: Maret | B4: 3 | D4: 2026 | F4: I | G4: Izin | I4: =DATE(2026,2,17) -> 46070 | J4: Tahun Baru Imlek 2577 Kongzili | L4: NON AKTIF | N4: Sembunyikan Karyawan OUT
A5: April | B5: 4 | D5: 2027 | F5: A | G5: Alfa / Tanpa Keterangan | I5: =DATE(2026,3,21) -> 46102 | J5: Hari Suci Nyepi Tahun Baru Saka 1948 | L5: CUTI | N5: Sembunyikan Karyawan Cuti
A6: Mei | B6: 5 | D6: 2028 | F6: C | G6: Cuti | I6: =DATE(2026,3,20) -> 46101 | J6: Hari Raya Idul Fitri 1447 H (Hari 1) | L6: RESIGN | N6: Hanya Karyawan Cuti
A7: Juni | B7: 6 | D7: 2029 | F7: OFF | G7: Libur / Off | I7: =DATE(2026,3,21) -> 46102 | J7: Hari Raya Idul Fitri 1447 H (Hari 2) | N7: Hanya Karyawan OUT
A8: Juli | B8: 7 | D8: 2030 | I8: =DATE(2026,4,3) -> 46115 | J8: Wafat Yesus Kristus
A9: Agustus | B9: 8 | I9: =DATE(2026,4,5) -> 46117 | J9: Hari Paskah
A10: September | B10: 9 | I10: =DATE(2026,5,1) -> 46143 | J10: Hari Buruh Internasional
A11: Oktober | B11: 10 | I11: =DATE(2026,5,14) -> 46156 | J11: Kenaikan Yesus Kristus
A12: November | B12: 11 | I12: =DATE(2026,5,27) -> 46169 | J12: Hari Raya Waisak 2570 BE
A13: Desember | B13: 12 | I13: =DATE(2026,5,28) -> 46170 | J13: Hari Raya Idul Adha 1447 H
I14: =DATE(2026,6,1) -> 46174 | J14: Hari Lahir Pancasila
I15: =DATE(2026,6,16) -> 46189 | J15: Tahun Baru Islam 1448 H
I16: =DATE(2026,8,17) -> 46251 | J16: Hari Kemerdekaan RI
I17: =DATE(2026,8,25) -> 46259 | J17: Maulid Nabi Muhammad SAW
I18: =DATE(2026,12,25) -> 46381 | J18: Hari Raya Natal

Sheet Ringkasan & Grafik
B2: RINGKASAN & STATISTIK KEHADIRAN BULANAN
B4: Periode Aktif: | C4: ='Absensi Bulanan'!E4 -> August 2026
B6: Kategori | C6: Kode | D6: Total Hari | E6: Persentase
B7: Hadir | C7: H | D7: ='Absensi Bulanan'!AJ301 -> 0 | E7: =IF(SUM(D$7:D$11)>0, D7/SUM(D$7:D$11), 0) -> 0
B8: Sakit | C8: S | D8: ='Absensi Bulanan'!AK301 -> 0 | E8: =IF(SUM(D$7:D$11)>0, D8/SUM(D$7:D$11), 0) -> 0
B9: Izin | C9: I | D9: ='Absensi Bulanan'!AL301 -> 0 | E9: =IF(SUM(D$7:D$11)>0, D9/SUM(D$7:D$11), 0) -> 0
B10: Alfa / Tanpa Keterangan | C10: A | D10: ='Absensi Bulanan'!AM301 -> 0 | E10: =IF(SUM(D$7:D$11)>0, D10/SUM(D$7:D$11), 0) -> 0
B11: Cuti | C11: C | D11: ='Absensi Bulanan'!AN301 -> 0 | E11: =IF(SUM(D$7:D$11)>0, D11/SUM(D$7:D$11), 0) -> 0
B14: STATISTIK STATUS KEPEGAWAIAN
B15: Status Kepegawaian | C15: Kode | D15: Total Karyawan | E15: Persentase
B16: Karyawan Aktif | C16: AKTIF | D16: =COUNTIF('Data Karyawan'!$F$4:$F$500, "AKTIF") -> 119 | E16: =IF(D21>0, D16/D21, 0) -> 1
B17: Karyawan Cuti | C17: CUTI | D17: =COUNTIF('Data Karyawan'!$F$4:$F$500, "CUTI") -> 0 | E17: =IF(D21>0, D17/D21, 0) -> 0
B18: Karyawan Non-Aktif | C18: NON AKTIF | D18: =COUNTIF('Data Karyawan'!$F$4:$F$500, "NON AKTIF") -> 0 | E18: =IF(D21>0, D18/D21, 0) -> 0
B19: Karyawan Resign | C19: RESIGN | D19: =COUNTIF('Data Karyawan'!$F$4:$F$500, "RESIGN") -> 0 | E19: =IF(D21>0, D19/D21, 0) -> 0
B20: Karyawan Keluar (OUT) | C20: OUT | D20: =COUNTIF('Data Karyawan'!$F$4:$F$500, "OUT") -> 0 | E20: =IF(D21>0, D20/D21, 0) -> 0
B21: Total Karyawan | C21: ALL | D21: =SUM(D16:D20) -> 119 | E21: =IF(D21>0, SUM(E16:E20), 0) -> 1
B24: TINGKAT KEHADIRAN AKTIF | E24: TOTAL KARYAWAN AKTIF | H24: TOTAL ALFA & SAKIT/IZIN | K24: KARYAWAN OUT / NON-AKTIF
B25: =IFERROR('Absensi Bulanan'!AO301, 0) -> 0 | E25: ='Ringkasan & Grafik'!D16 -> 119 | H25: ='Absensi Bulanan'!AK301 + 'Absensi Bulanan'!AL301 + 'Absensi Bulanan'!AM301 -> 0 | K25: ='Ringkasan & Grafik'!D18 + 'Ringkasan & Grafik'!D19 + 'Ringkasan & Grafik'!D20 -> 0
